const { isFunction, get, isEmpty, template } = require('lodash')
const falsey = require('falsey')

const conf = require('@condo/config')
const { getTranslations } = require('@condo/locales/loader')

const EXTRA_LOGGING = falsey(get(process, 'env.DISABLE_LOGGING'))

/**
 * Implements correct expecting of GraphQLError, thrown by Keystone.
 * Expectation checks inside of `catch` are not covering a case,
 * when no exception is thrown, â€” test will pass, but should fail.
 * https://stackoverflow.com/questions/48707111/asserting-against-thrown-error-objects-in-jest
 *
 * @example
 * await catchErrorFrom(async () => {
 *     await doSomethingThatShouldThrowAnError()
 * }, (e) => {
 *     // any `expect` checks for catched error
 * })
 *
 *
 * @param {() => Promise<*>} testFunc - Function, expected to throw an error
 * @param {(Error) => void} inspect - Function, that should inspect the error in details
 * @return {Promise<*>}
 */
const catchErrorFrom = async (testFunc, inspect) => {
    if (testFunc.constructor.name !== 'AsyncFunction') throw new Error('catchErrorFrom( testFunc ) testFunc is not an AsyncFunction!')
    if (!isFunction(inspect)) throw new Error('catchErrorFrom( inspect ) inspect is not a function!')
    let thrownError = null
    try {
        await testFunc()
    } catch (e) {
        if (EXTRA_LOGGING) console.warn('catchErrorFrom() caught error:', e)
        thrownError = e
    }
    if (!thrownError) throw new Error(`catchErrorFrom() no caught error for: ${testFunc}`)
    return inspect(thrownError)
}

/**
 * Expects a GraphQLError of type 'AccessDeniedError', thrown by Keystone on access to a specified path.
 * Should be used to examine access to operation of GraphQL utility wrapper for complex paths.
 * If path is skipped, than nor it, neither value won't be checked. This option is useful,
 * when we have unstable errors contents, for example when there are sub-requests that are executed in parallel
 * and we get different errors, depending on which sub-request finishes first.
 * @example
 *
 * test('something, that should throw an error', async () => {
 *     const userClient = await makeClientWithNewRegisteredAndLoggedInUser()
 *     await expectToThrowAccessDeniedError(
 *         async () => await createTestResident(userClient, ...),
 *         'objs',
 *     )
 * })
 *
 * @param {() => Promise<void>} testFunc - Function, expected to throw an error
 * @param {String} path - path
 * @return {Promise<void>}
 */
const expectToThrowAccessDeniedError = async (testFunc, path) => {
    if (!path) throw new Error('expectToThrowAccessDeniedError(): no path argument')
    await catchErrorFrom(testFunc, (caught) => {
        expect(caught).toMatchObject({
            name: 'TestClientResponseError',
            data: { [path]: null },
            errors: [expect.objectContaining({
                'message': 'You do not have access to this resource',
                'name': 'AccessDeniedError',
                'path': [path],
                'locations': [expect.objectContaining({
                    line: expect.anything(),
                    column: expect.anything(),
                })],
                'extensions': {
                    'code': 'INTERNAL_SERVER_ERROR',
                },
            })],
        })
    })
}

const expectToThrowAccessDeniedErrorToObj = async (testFunc) => {
    await expectToThrowAccessDeniedError(testFunc, 'obj')
}

const expectToThrowAccessDeniedErrorToObjects = async (testFunc) => {
    await expectToThrowAccessDeniedError(testFunc, 'objs')
}

const expectToThrowAccessDeniedErrorToResult = async (testFunc) => {
    await expectToThrowAccessDeniedError(testFunc, 'result')
}

/**
 * Expects a GraphQL 'AuthenticationError' Error, thrown by access check if case of UNAUTHENTICATED user access.
 * Should be used to examine access to `getAll` GraphQL utility wrapper, that returns `objs`.
 * @example
 *
 * test('something, that should throw an error', async () => {
 *     const client = await makeClient()
 *     await expectToThrowAuthenticationError(
 *         async () => await Organization.getAll(client),
 *         'obj',
 *     )
 * })
 *
 * @param {() => Promise<void>} testFunc - Function, expected to throw an error
 * @param {String} path - path
 * @return {Promise<void>}
 */
const expectToThrowAuthenticationError = async (testFunc, path) => {
    if (!path) throw new Error('expectToThrowAccessDeniedError(): no path argument')
    await catchErrorFrom(testFunc, (caught) => {
        expect(caught).toMatchObject({
            name: 'TestClientResponseError',
            data: { [path]: null },
            errors: [expect.objectContaining({
                'message': 'No or incorrect authentication credentials',
                'name': 'AuthenticationError',
                'path': [path],
                'extensions': {
                    'code': 'UNAUTHENTICATED',
                },
            })],
        })
    })
}

const expectToThrowAuthenticationErrorToObj = async (testFunc) => {
    await expectToThrowAuthenticationError(testFunc, 'obj')
}

const expectToThrowAuthenticationErrorToObjects = async (testFunc) => {
    await expectToThrowAuthenticationError(testFunc, 'objs')
}

const expectToThrowAuthenticationErrorToResult = async (testFunc) => {
    await expectToThrowAuthenticationError(testFunc, 'result')
}

const expectToThrowValidationFailureError = async (testFunc, message, path = 'obj') => {
    if (!message) throw new Error('expectToThrowValidationFailureError(): no message argument')
    await catchErrorFrom(testFunc, (caught) => {
        expect(caught).toMatchObject({
            name: 'TestClientResponseError',
            data: { [path]: null },
            errors: [expect.objectContaining({
                "message": "You attempted to perform an invalid mutation",
                'name': 'ValidationFailureError',
                'path': [path],
                'locations': [expect.objectContaining({
                    line: expect.anything(),
                    column: expect.anything(),
                })],
                'extensions': {
                    'code': 'INTERNAL_SERVER_ERROR',
                },
            })],
        })

        // TODO(pahaz): you really don't have access to originalError in production! need to change this check!
        expect(caught.errors[0]).toMatchObject({
            originalError: {
                data: {
                    messages: expect.arrayContaining([
                        expect.stringContaining(message),
                    ]),
                },
            },
        })
    })
}

const expectToThrowInternalError = async (testFunc, message, path = 'obj') => {
    if (!message) throw new Error('expectToThrowInternalError(): no message argument')
    await catchErrorFrom(testFunc, (caught) => {
        expect(caught).toMatchObject({
            name: 'TestClientResponseError',
            data: { [path]: null },
            errors: [expect.objectContaining({
                'message': expect.stringContaining(message),
                'name': 'GraphQLError',
                'path': [path],
                'locations': [expect.objectContaining({
                    line: expect.anything(),
                    column: expect.anything(),
                })],
                'extensions': {
                    'code': 'INTERNAL_SERVER_ERROR',
                },
            })],
        })
    })
}

const expectToThrowGQLError = async (testFunc, errorFields, path = 'obj') => {
    if (isEmpty(errorFields) || typeof errorFields !== 'object') throw new Error('expectToThrowGQLError(): wrong errorFields argument')
    if (!errorFields.code || !errorFields.type) throw new Error('expectToThrowGQLError(): errorFields argument: no code or no type')
    let interpolatedMessageForUser
    if (errorFields.messageForUser) {
        const locale = conf.DEFAULT_LOCALE
        const translations = getTranslations(locale)
        const translatedMessage = translations[errorFields.messageForUser]
        interpolatedMessageForUser = template(translatedMessage)(errorFields.messageInterpolation)
        if (!interpolatedMessageForUser) throw new Error(`expectToThrowGQLError(): you need to set ${errorFields.messageForUser} for locale=${locale}`)
    }
    const message = template(errorFields.message)(errorFields.messageInterpolation)

    await catchErrorFrom(testFunc, (caught) => {
        expect(caught).toMatchObject({
            name: 'TestClientResponseError',
            data: { [path]: null },
            errors: [expect.objectContaining({
                'message': message,
                'name': 'GQLError',
                'path': [path],
                'locations': [expect.objectContaining({
                    line: expect.anything(),
                    column: expect.anything(),
                })],
                'extensions': {
                    ...errorFields,
                    messageForUser: interpolatedMessageForUser,
                },
            })],
        })
    })
}

const expectToThrowGraphQLRequestError = async (testFunc, message) => {
    if (!message) throw new Error('expectToThrowGraphQLRequestError(): no message argument')
    await catchErrorFrom(testFunc, (caught) => {
        expect(caught).toMatchObject({
            name: 'TestClientResponseError',
        })

        const { errors, data } = caught
        expect(data).toBeUndefined()
        expect(errors).toHaveLength(1)
        expect(errors[0].message).toMatch(message)
        // NOTE(pahaz):
        //  ValidationError - The GraphQL operation is not valid against the server's schema.
        //  UserInputError - The GraphQL operation includes an invalid value for a field argument.
        //  SyntaxError - The GraphQL operation string contains a syntax error.
        expect(errors[0].name).toMatch(/(UserInputError|ValidationError|SyntaxError)/)
    })
}

/**
 * HAVE a BUG HERE!
 * @deprecated
 */
const expectToThrowMutationError = async (testFunc, messageContains, path = ['result'], name = 'GraphQLError') => {
    await catchErrorFrom(testFunc, ({ errors }) => {
        expect(errors[0]).toMatchObject({
            message: expect.stringContaining(messageContains),
            name,
            path,
        })
    })
}

/**
 * HAVE a BUG HERE! Use `expectToThrowGraphQLRequestError`
 * @deprecated
 */
const expectToThrowUserInputError = async (testFunc, messageContains, name = 'UserInputError') => {
    await catchErrorFrom(testFunc, ({ errors }) => {
        expect(errors[0]).toMatchObject({
            message: expect.stringContaining(messageContains),
            name,
        })
    })
}

module.exports = {
    catchErrorFrom,
    expectToThrowAccessDeniedError,
    expectToThrowAccessDeniedErrorToObj,
    expectToThrowAccessDeniedErrorToObjects,
    expectToThrowAccessDeniedErrorToResult,
    expectToThrowAuthenticationError,
    expectToThrowAuthenticationErrorToObj,
    expectToThrowAuthenticationErrorToObjects,
    expectToThrowAuthenticationErrorToResult,
    expectToThrowValidationFailureError,
    expectToThrowInternalError,
    expectToThrowGQLError,
    expectToThrowGraphQLRequestError,
    expectToThrowMutationError,
    expectToThrowUserInputError,
}
